Workbook

Sheet FORECAST APP
A1: CHAVE | B1: CHAVE 2 | C1: GERENTE | D1: COORDENAÇÃO | E1: VENDEDOR | F1: CLIFOR | G1: CLIENTE | H1: UF | I1: EMPRESA | J1: CATEGORIA | K1: SHARE (%) | L1: FEVEREIRO 2025 | M1: MÉDIA 6M | N1: MÉDIA 3M | O1: META FEVEREIRO | P1: SELL OUT (e-Sales) | Q1: R+C | R1: ESTOQUE | S1: FORECAST 02 | T1: FORECAST 16 | U1: FORECAST 23 | V1: MARGEM/KG
A2: =J2&I2 -> LPI 25KGLACTALIS | B2: =F2&J2&I2 -> 5115621LPI 25KGLACTALIS | C2: MAURICIO | D2: JOEL | E2: DLUM | F2: 5115621 | G2: MARAJOARA INDUSTRIA DE LATICINI | H2: GO | I2: LACTALIS | J2: LPI 25KG | K2: 0 | L2: 0 | M2: -333.33333 | N2: 0 | O2: 10327.385 | P2: 0 | Q2: 0 | R2: 0 | S2: 0 | T2: 0 | U2: 0 | V2: =VLOOKUP(A2,Planilha1!B:E,4,0) -> -4.3046759
A3: =J3&I3 -> COMPOSTOITAMBÉ | B3: =F3&J3&I3 -> 5173427COMPOSTOITAMBÉ | C3: MAURICIO | D3: JOEL | E3: DUAS RODAS | F3: 5173427 | G3: DISTRIPACK DIST DE EMBALAGENS LTDA | H3: MG | I3: ITAMBÉ | J3: COMPOSTO | K3: 0 | L3: 0 | M3: 3637.5 | N3: 4000 | O3: 4825.3004 | P3: 0 | Q3: 12000 | R3: 0 | S3: 0 | T3: 12000 | U3: 0 | V3: =VLOOKUP(A3,Planilha1!B:E,4,0) -> 0.15618218
A4: =J4&I4 -> LPI 25KGITAMBÉ | B4: =F4&J4&I4 -> 5012038LPI 25KGITAMBÉ | C4: MAURICIO | D4: TATIANA NITTA | E4: TATIANA NITTA | F4: 5012038 | G4: HARALD INDUSTRIA E COMERCIO ALI | H4: SP | I4: ITAMBÉ | J4: LPI 25KG | K4: 0 | L4: 0 | M4: 4000 | N4: 8000 | O4: 0 | P4: 0 | Q4: 48000 | R4: 0 | S4: 0 | T4: 48000 | U4: 0 | V4: =VLOOKUP(A4,Planilha1!B:E,4,0) -> -1.2181928
A5: =J5&I5 -> LEITE CONDENSADOITAMBÉ | B5: =F5&J5&I5 -> 5223996LEITE CONDENSADOITAMBÉ | C5: MAURICIO | D5: JOEL | E5: DUAS RODAS | F5: 5223996 | G5: PLASTIC DISTRIBUIDORA LTDA | H5: ES | I5: ITAMBÉ | J5: LEITE CONDENSADO | K5: 0 | L5: 0 | M5: 31.995 | N5: 0 | O5: 126.99771 | P5: 0 | Q5: 129.02 | R5: 0 | S5: 0 | T5: 0 | U5: 0 | V5: =VLOOKUP(A5,Planilha1!B:E,4,0) -> 1.4766793
A6: =J6&I6 -> CREME UHTITAMBÉ | B6: =F6&J6&I6 -> 5223996CREME UHTITAMBÉ | C6: MAURICIO | D6: JOEL | E6: DUAS RODAS | F6: 5223996 | G6: PLASTIC DISTRIBUIDORA LTDA | H6: ES | I6: ITAMBÉ | J6: CREME UHT | K6: 0 | L6: 0 | M6: 0.16833333 | N6: 0 | O6: 18.999261 | P6: 0 | Q6: 32.4 | R6: 0 | S6: 0 | T6: 0 | U6: 0 | V6: =VLOOKUP(A6,Planilha1!B:E,4,0) -> 1.236254
A7: =J7&I7 -> COMPOSTOITAMBÉ | B7: =F7&J7&I7 -> 5224563COMPOSTOITAMBÉ | C7: MAURICIO | D7: JOEL | E7: DUAS RODAS | F7: 5224563 | G7: MC DAVE S INDUSTRIA DE SORVETES | H7: AM | I7: ITAMBÉ | J7: COMPOSTO | K7: 0 | L7: 0 | M7: 416.66667 | N7: 833.33333 | O7: 521.57706 | P7: 0 | Q7: 0 | R7: 0 | S7: 0 | T7: 0 | U7: 0 | V7: =VLOOKUP(A7,Planilha1!B:E,4,0) -> 0.15618218
A8: =J8&I8 -> COMPOSTOITAMBÉ | B8: =F8&J8&I8 -> 5313336COMPOSTOITAMBÉ | C8: MAURICIO | D8: JOEL | E8: DUAS RODAS | F8: 5313336 | G8: M C COMERCIO DE DOCES E | H8: AM | I8: ITAMBÉ | J8: COMPOSTO | K8: 0 | L8: 0 | M8: 333.33333 | N8: 0 | O8: 463.14903 | P8: 0 | Q8: 0 | R8: 0 | S8: 0 | T8: 0 | U8: 0 | V8: =VLOOKUP(A8,Planilha1!B:E,4,0) -> 0.15618218
A9: =J9&I9 -> COMPOSTOITAMBÉ | B9: =F9&J9&I9 -> 5319281COMPOSTOITAMBÉ | C9: MAURICIO | D9: JOEL | E9: DUAS RODAS | F9: 5319281 | G9: DISPPAN DIST DE PROD PANIFICACAO | H9: AM | I9: ITAMBÉ | J9: COMPOSTO | K9: 0 | L9: 10000 | M9: 1037.5 | N9: 0 | O9: 8114.371 | P9: 0 | Q9: 0 | R9: 0 | S9: 0 | T9: 0 | U9: 0 | V9: =VLOOKUP(A9,Planilha1!B:E,4,0) -> 0.15618218
A10: =J10&I10 -> COMPOSTOITAMBÉ | B10: =F10&J10&I10 -> 5335635COMPOSTOITAMBÉ | C10: MAURICIO | D10: JOEL | E10: DUAS RODAS | F10: 5335635 | G10: SUSANA SALES SIQUEIRA 159179698 | H10: BA | I10: ITAMBÉ | J10: COMPOSTO | K10: 0 | L10: 0 | M10: 141.66667 | N10: 0 | O10: 393.32041 | P10: 0 | Q10: 0 | R10: 0 | S10: 0 | T10: 0 | U10: 0 | V10: =VLOOKUP(A10,Planilha1!B:E,4,0) -> 0.15618218
A11: =J11&I11 -> LPD 25KGLACTALIS | B11: =F11&J11&I11 -> 5219478LPD 25KGLACTALIS | C11: MAURICIO | D11: JOEL | E11: FERREIRA MELO | F11: 5219478 | G11: YAKULT SA INDUSTRIA E COMERCIO | H11: SP | I11: LACTALIS | J11: LPD 25KG | K11: 0 | L11: 648000 | M11: 74970.833 | N11: 100000 | O11: 29872.139 | P11: 0 | Q11: 0 | R11: 0 | S11: 0 | T11: 0 | U11: 0 | V11: =VLOOKUP(A11,Planilha1!B:E,4,0) -> 5.8936291
A12: =J12&I12 -> LEITE CONDENSADOITAMBÉ | B12: =F12&J12&I12 -> 5019640LEITE CONDENSADOITAMBÉ | C12: MAURICIO | D12: JOEL | E12: HENRIQUE FERREIRA | F12: 5019640 | G12: BIG CHURROS DE PIRACICABA LTDA | H12: SP | I12: ITAMBÉ | J12: LEITE CONDENSADO | K12: 0 | L12: 0 | M12: 8.3333333 | N12: 0 | O12: 263.99525 | P12: 0 | Q12: 0 | R12: 0 | S12: 0 | T12: 0 | U12: 0 | V12: =VLOOKUP(A12,Planilha1!B:E,4,0) -> 1.4766793
A13: =J13&I13 -> DOCE DE LEITEITAMBÉ | B13: =F13&J13&I13 -> 5019640DOCE DE LEITEITAMBÉ | C13: MAURICIO | D13: JOEL | E13: HENRIQUE FERREIRA | F13: 5019640 | G13: BIG CHURROS DE PIRACICABA LTDA | H13: SP | I13: ITAMBÉ | J13: DOCE DE LEITE | K13: 0 | L13: 1590 | M13: 483.33333 | N13: 460 | O13: 394.02252 | P13: 0 | Q13: 240 | R13: 0 | S13: 0 | T13: 240 | U13: 0 | V13: =VLOOKUP(A13,Planilha1!B:E,4,0) -> 5.8210744
... A3230: =J3230&I3230 -> LEITE UHTLACTALIS | B3230: =F3230&J3230&I3230 -> 5363097LEITE UHTLACTALIS | C3230: RODRIGO | D3230: ALEXANDRO | E3230: CLIENTE FLAC | F3230: 5363097 | G3230: PDO ALIMENTOS E COME SOCIE EMPR | H3230: SP | I3230: LACTALIS | J3230: LEITE UHT | K3230: 0 | L3230: 0 | M3230: 0 | N3230: 0 | O3230: 0 | P3230: 0 | Q3230: 0 | R3230: 0 | S3230: 0 | T3230: 0 | U3230: 0 | V3230: =VLOOKUP(A3230,Planilha1!B:E,4,0) -> 0.37177548
A3231: =J3231&I3231 -> LEITE UHTLACTALIS | B3231: =F3231&J3231&I3231 -> 5363801LEITE UHTLACTALIS | C3231: #N/A | D3231: #N/A | E3231: #N/A | F3231: 5363801 | G3231: Não Atribuído | H3231: SP | I3231: LACTALIS | J3231: LEITE UHT | K3231: 0 | L3231: 0 | M3231: 0 | N3231: 0 | O3231: 0 | P3231: 0 | Q3231: 0 | R3231: 0 | S3231: 0 | T3231: 0 | U3231: 0 | V3231: =VLOOKUP(A3231,Planilha1!B:E,4,0) -> 0.37177548
A3232: =J3232&I3232 -> LPD 25KGITAMBÉ | B3232: =F3232&J3232&I3232 -> 5059695LPD 25KGITAMBÉ | C3232: MAURICIO | D3232: TATIANA NITTA | E3232: TATIANA NITTA | F3232: 5059695 | G3232: POLENGHI INDUSTRIAS ALIMS LTDA | H3232: SP | I3232: ITAMBÉ | J3232: LPD 25KG | K3232: 0 | L3232: 0 | M3232: 0 | N3232: 0 | O3232: 0 | P3232: 0 | Q3232: 0 | R3232: 0 | S3232: 0 | T3232: 0 | U3232: 0 | V3232: =VLOOKUP(A3232,Planilha1!B:E,4,0) -> 3.3372177
A3233: =J3233&I3233 -> LPD 25KGITAMBÉ | B3233: =F3233&J3233&I3233 -> 5220627LPD 25KGITAMBÉ | C3233: RODRIGO | D3233: JESSICA | E3233: LUCIANA MARTINS | F3233: 5220627 | G3233: JME RAUTA COMERCIAL DISTRIBUIDORA | H3233: RJ | I3233: ITAMBÉ | J3233: LPD 25KG | K3233: 0 | L3233: 0 | M3233: 0 | N3233: 0 | O3233: 0 | P3233: 0 | Q3233: 0 | R3233: 0 | S3233: 0 | T3233: 0 | U3233: 0 | V3233: =VLOOKUP(A3233,Planilha1!B:E,4,0) -> 3.3372177
A3234: =J3234&I3234 -> LPD 25KGITAMBÉ | B3234: =F3234&J3234&I3234 -> 5353050LPD 25KGITAMBÉ | C3234: MAURICIO | D3234: TATIANA NITTA | E3234: TATIANA NITTA | F3234: 5353050 | G3234: ALIBEY IND E COM DE ALIM E LTDA | H3234: SP | I3234: ITAMBÉ | J3234: LPD 25KG | K3234: 0 | L3234: 0 | M3234: 0 | N3234: 166.66667 | O3234: 0 | P3234: 0 | Q3234: 0 | R3234: 0 | S3234: 0 | T3234: 0 | U3234: 0 | V3234: =VLOOKUP(A3234,Planilha1!B:E,4,0) -> 3.3372177
A3235: =J3235&I3235 -> LPI 25KGITAMBÉ | B3235: =F3235&J3235&I3235 -> 5063322LPI 25KGITAMBÉ | C3235: RODRIGO | D3235: CELIO MARTINS | E3235: MARCELO SILVA | F3235: 5063322 | G3235: C D A DISTRIBUIDORA DE ALIMENTO | H3235: MG | I3235: ITAMBÉ | J3235: LPI 25KG | K3235: 0 | L3235: 0 | M3235: 0 | N3235: 166.66667 | O3235: 0 | P3235: 0 | Q3235: 0 | R3235: 0 | S3235: 0 | T3235: 0 | U3235: 0 | V3235: =VLOOKUP(A3235,Planilha1!B:E,4,0) -> -1.2181928
A3236: =J3236&I3236 -> LPI 25KGITAMBÉ | B3236: =F3236&J3236&I3236 -> 5157986LPI 25KGITAMBÉ | C3236: MAURICIO | D3236: JOEL | E3236: JOEL ELEOTÉRIO | F3236: 5157986 | G3236: INDUSTRIA E COM DE PROD ALIM GELONI | H3236: PR | I3236: ITAMBÉ | J3236: LPI 25KG | K3236: 0 | L3236: 0 | M3236: 0 | N3236: 4666.6667 | O3236: 0 | P3236: 0 | Q3236: 0 | R3236: 0 | S3236: 0 | T3236: 0 | U3236: 0 | V3236: =VLOOKUP(A3236,Planilha1!B:E,4,0) -> -1.2181928
A3237: =J3237&I3237 -> LPI 25KGITAMBÉ | B3237: =F3237&J3237&I3237 -> 5176952LPI 25KGITAMBÉ | C3237: RODRIGO | D3237: ALEXANDRO | E3237: EMMANUEL FRANCISCO | F3237: 5176952 | G3237: CLUBE DO CONFEITEIRO LTDA | H3237: SP | I3237: ITAMBÉ | J3237: LPI 25KG | K3237: 0 | L3237: 0 | M3237: 0 | N3237: 83.333333 | O3237: 0 | P3237: 0 | Q3237: 0 | R3237: 0 | S3237: 0 | T3237: 0 | U3237: 0 | V3237: =VLOOKUP(A3237,Planilha1!B:E,4,0) -> -1.2181928
A3238: =J3238&I3238 -> LPI 25KGITAMBÉ | B3238: =F3238&J3238&I3238 -> 5206787LPI 25KGITAMBÉ | C3238: PEDRO | D3238: ANA MENIQUETE | E3238: ANA MENIQUETE | F3238: 5206787 | G3238: CS FABRICACAO DE ALIMENTOS | H3238: SP | I3238: ITAMBÉ | J3238: LPI 25KG | K3238: 0 | L3238: 0 | M3238: 0 | N3238: 100 | O3238: 0 | P3238: 0 | Q3238: 0 | R3238: 0 | S3238: 0 | T3238: 0 | U3238: 0 | V3238: =VLOOKUP(A3238,Planilha1!B:E,4,0) -> -1.2181928
A3239: =J3239&I3239 -> LPI 25KGITAMBÉ | B3239: =F3239&J3239&I3239 -> 5232803LPI 25KGITAMBÉ | C3239: MAURICIO | D3239: JOEL | E3239: HENRIQUE FERREIRA | F3239: 5232803 | G3239: L GONZAGA MIX AMBIENTAL | H3239: SP | I3239: ITAMBÉ | J3239: LPI 25KG | K3239: 0 | L3239: 0 | M3239: 0 | N3239: 5000 | O3239: 0 | P3239: 0 | Q3239: 0 | R3239: 0 | S3239: 0 | T3239: 0 | U3239: 0 | V3239: =VLOOKUP(A3239,Planilha1!B:E,4,0) -> -1.2181928
A3240: =J3240&I3240 -> LPI 25KGITAMBÉ | B3240: =F3240&J3240&I3240 -> 5318875LPI 25KGITAMBÉ | C3240: RODRIGO | D3240: CELIO MARTINS | E3240: CELIO/MARANATHA | F3240: 5318875 | G3240: OESA COMERCIO E REPRESENTACOES | H3240: MG | I3240: ITAMBÉ | J3240: LPI 25KG | K3240: 0 | L3240: 0 | M3240: 0 | N3240: 8.3333333 | O3240: 0 | P3240: 0 | Q3240: 125 | R3240: 0 | S3240: 0 | T3240: 0 | U3240: 0 | V3240: =VLOOKUP(A3240,Planilha1!B:E,4,0) -> -1.2181928
A3241: =J3241&I3241 -> LPI 25KGITAMBÉ | B3241: =F3241&J3241&I3241 -> 5341743LPI 25KGITAMBÉ | C3241: MAURICIO | D3241: JOEL | E3241: JOEL ELEOTÉRIO | F3241: 5341743 | G3241: MAURO SIQUEIRA DE MOURA JUNIOR | H3241: SP | I3241: ITAMBÉ | J3241: LPI 25KG | K3241: 0 | L3241: 0 | M3241: 0 | N3241: 16666.667 | O3241: 0 | P3241: 0 | Q3241: 0 | R3241: 0 | S3241: 0 | T3241: 0 | U3241: 0 | V3241: =VLOOKUP(A3241,Planilha1!B:E,4,0) -> -1.2181928
A3242: =J3242&I3242 -> LPI 25KGITAMBÉ | B3242: =F3242&J3242&I3242 -> 5360926LPI 25KGITAMBÉ | C3242: MAURICIO | D3242: JOEL | E3242: HENRIQUE FERREIRA | F3242: 5360926 | G3242: MISTER DISTRIBUIDORA LTDA | H3242: MA | I3242: ITAMBÉ | J3242: LPI 25KG | K3242: 0 | L3242: 0 | M3242: 0 | N3242: 166.66667 | O3242: 0 | P3242: 0 | Q3242: 0 | R3242: 0 | S3242: 0 | T3242: 0 | U3242: 0 | V3242: =VLOOKUP(A3242,Planilha1!B:E,4,0) -> -1.2181928
A3243: =J3243&I3243 -> LPI 25KGLACTALIS | B3243: =F3243&J3243&I3243 -> 5010931LPI 25KGLACTALIS | C3243: MAURICIO | D3243: MARCELO | E3243: MARCELO RODRIGUES | F3243: 5010931 | G3243: SAO FRANCISCO IND DE ALIMENTOS | H3243: PR | I3243: LACTALIS | J3243: LPI 25KG | K3243: 0 | L3243: 0 | M3243: 0 | N3243: 33.333333 | O3243: 0 | P3243: 0 | Q3243: 0 | R3243: 0 | S3243: 0 | T3243: 0 | U3243: 0 | V3243: =VLOOKUP(A3243,Planilha1!B:E,4,0) -> -4.3046759
... A3729: =J3729&I3729 -> COMPOSTOITAMBÉ | B3729: =F3729&J3729&I3729 -> 5189644COMPOSTOITAMBÉ | C3729: RODRIGO | D3729: ALEXANDRO | E3729: EMMANUEL FRANCISCO | F3729: 5189644 | G3729: BOCAO COMERCIO DE DOCES LTDA | H3729: SP | I3729: ITAMBÉ | J3729: COMPOSTO | K3729: 0 | L3729: 0 | M3729: 0 | N3729: 0 | O3729: 0 | P3729: 0 | Q3729: 0 | R3729: 0 | S3729: 10 | T3729: 10 | U3729: 10 | V3729: =VLOOKUP(A3729,Planilha1!B:E,4,0) -> 0.15618218
A3730: =J3730&I3730 -> CREME UHTITAMBÉ | B3730: =F3730&J3730&I3730 -> 5105392CREME UHTITAMBÉ | C3730: #N/A | D3730: #N/A | E3730: #N/A | F3730: 5105392 | G3730: Não Atribuído | H3730: NA | I3730: ITAMBÉ | J3730: CREME UHT | K3730: 0 | L3730: 0 | M3730: 0 | N3730: 0 | O3730: 0 | P3730: 0 | Q3730: 0 | R3730: 0 | S3730: 12 | T3730: 12 | U3730: 0 | V3730: =VLOOKUP(A3730,Planilha1!B:E,4,0) -> 1.236254
A3731: =J3731&I3731 -> DOCE DE LEITEITAMBÉ | B3731: =F3731&J3731&I3731 -> 5105392DOCE DE LEITEITAMBÉ | C3731: #N/A | D3731: #N/A | E3731: #N/A | F3731: 5105392 | G3731: Não Atribuído | H3731: NA | I3731: ITAMBÉ | J3731: DOCE DE LEITE | K3731: 0 | L3731: 0 | M3731: 0 | N3731: 0 | O3731: 0 | P3731: 0 | Q3731: 0 | R3731: 0 | S3731: 20 | T3731: 20 | U3731: 0 | V3731: =VLOOKUP(A3731,Planilha1!B:E,4,0) -> 5.8210744
A3732: =J3732&I3732 -> LEITE CONDENSADOITAMBÉ | B3732: =F3732&J3732&I3732 -> 5105392LEITE CONDENSADOITAMBÉ | C3732: #N/A | D3732: #N/A | E3732: #N/A | F3732: 5105392 | G3732: Não Atribuído | H3732: NA | I3732: ITAMBÉ | J3732: LEITE CONDENSADO | K3732: 0 | L3732: 0 | M3732: 0 | N3732: 0 | O3732: 0 | P3732: 0 | Q3732: 0 | R3732: 0 | S3732: 200 | T3732: 200 | U3732: 0 | V3732: =VLOOKUP(A3732,Planilha1!B:E,4,0) -> 1.4766793
A3733: =J3733&I3733 -> LEITE CONDENSADOITAMBÉ | B3733: =F3733&J3733&I3733 -> 5335628LEITE CONDENSADOITAMBÉ | C3733: RODRIGO | D3733: CELIO MARTINS | E3733: CELIO MARTINS | F3733: 5335628 | G3733: COMERCIO E REPRESENTACOES CECOT | H3733: MG | I3733: ITAMBÉ | J3733: LEITE CONDENSADO | K3733: 0 | L3733: 0 | M3733: 0 | N3733: 0 | O3733: 0 | P3733: 0 | Q3733: 0 | R3733: 0 | S3733: 0 | T3733: 0 | U3733: 510 | V3733: =VLOOKUP(A3733,Planilha1!B:E,4,0) -> 1.4766793
A3734: =J3734&I3734 -> LEITE EM PÓITAMBÉ | B3734: =F3734&J3734&I3734 -> 5105392LEITE EM PÓITAMBÉ | C3734: #N/A | D3734: #N/A | E3734: #N/A | F3734: 5105392 | G3734: Não Atribuído | H3734: NA | I3734: ITAMBÉ | J3734: LEITE EM PÓ | K3734: 0 | L3734: 0 | M3734: 0 | N3734: 0 | O3734: 0 | P3734: 0 | Q3734: 0 | R3734: 0 | S3734: 0 | T3734: 0 | U3734: 0 | V3734: =VLOOKUP(A3734,Planilha1!B:E,4,0) -> 4.5971523
A3735: =J3735&I3735 -> LEITE UHTLACTALIS | B3735: =F3735&J3735&I3735 -> 5273270LEITE UHTLACTALIS | C3735: RODRIGO | D3735: ALEXANDRO | E3735: CLIENTE FLAC | F3735: 5273270 | G3735: AAP CASTRO E FERNANDES LTDA | H3735: SP | I3735: LACTALIS | J3735: LEITE UHT | K3735: 0 | L3735: 0 | M3735: 0 | N3735: 0 | O3735: 0 | P3735: 0 | Q3735: 0 | R3735: 0 | S3735: 0 | T3735: 0 | U3735: 0 | V3735: =VLOOKUP(A3735,Planilha1!B:E,4,0) -> 0.37177548
A3736: =J3736&I3736 -> LEITE UHTLACTALIS | B3736: =F3736&J3736&I3736 -> 5291710LEITE UHTLACTALIS | C3736: RODRIGO | D3736: ALEXANDRO | E3736: CLIENTE FLAC | F3736: 5291710 | G3736: MARQUES FABRICACAO E COMERC ALIM LT | H3736: SP | I3736: LACTALIS | J3736: LEITE UHT | K3736: 0 | L3736: 0 | M3736: 0 | N3736: 0 | O3736: 0 | P3736: 0 | Q3736: 0 | R3736: 0 | S3736: 0 | T3736: 0 | U3736: 0 | V3736: =VLOOKUP(A3736,Planilha1!B:E,4,0) -> 0.37177548
A3737: =J3737&I3737 -> LPD 25KGLACTALIS | B3737: =F3737&J3737&I3737 -> 5143169LPD 25KGLACTALIS | C3737: MAURICIO | D3737: MARCELO | E3737: MARCELO RODRIGUES | F3737: 5143169 | G3737: LATICINIOS TIROLEZ LTDA | H3737: SP | I3737: LACTALIS | J3737: LPD 25KG | K3737: 0 | L3737: 12000 | M3737: 6041.6667 | N3737: 5500 | O3737: 1767.2624 | P3737: 0 | Q3737: 0 | R3737: 0 | S3737: 0 | T3737: 0 | U3737: 0 | V3737: =VLOOKUP(A3737,Planilha1!B:E,4,0) -> 5.8936291
A3738: =J3738&I3738 -> MANTEIGA 5KGITAMBÉ | B3738: =F3738&J3738&I3738 -> 5352254MANTEIGA 5KGITAMBÉ | C3738: PEDRO | D3738: AMANDA | E3738: AMANDA CARVALHO | F3738: 5352254 | G3738: COCO BAMBU SUL PIZZARIA LTDA | H3738: CE | I3738: ITAMBÉ | J3738: MANTEIGA 5KG | K3738: 0 | L3738: 0 | M3738: 0 | N3738: 0 | O3738: 0 | P3738: 0 | Q3738: 40 | R3738: 0 | S3738: 0 | T3738: 0 | U3738: 60 | V3738: =VLOOKUP(A3738,Planilha1!B:E,4,0) -> 5.8198005
A3739: =J3739&I3739 -> MANTEIGA 5KGITAMBÉ | B3739: =F3739&J3739&I3739 -> 5352264MANTEIGA 5KGITAMBÉ | C3739: PEDRO | D3739: AMANDA | E3739: AMANDA CARVALHO | F3739: 5352264 | G3739: DOM PASTEL ALIMENTOS LTDA | H3739: CE | I3739: ITAMBÉ | J3739: MANTEIGA 5KG | K3739: 0 | L3739: 0 | M3739: 0 | N3739: 0 | O3739: 0 | P3739: 0 | Q3739: 0 | R3739: 0 | S3739: 0 | T3739: 0 | U3739: 50 | V3739: =VLOOKUP(A3739,Planilha1!B:E,4,0) -> 5.8198005
A3740: =J3740&I3740 -> MERC + AROMITAMBÉ | B3740: =F3740&J3740&I3740 -> 5008636MERC + AROMITAMBÉ | C3740: PEDRO | D3740: AMANDA | E3740: NUTRI | F3740: 5008636 | G3740: GR SERVICOS E ALIMENTACAO LTDA | H3740: RJ | I3740: ITAMBÉ | J3740: MERC + AROM | K3740: 0 | L3740: 0 | M3740: 0 | N3740: 0 | O3740: 0 | P3740: 0 | Q3740: 972 | R3740: 0 | S3740: 0 | T3740: 0 | U3740: 0 | V3740: =VLOOKUP(A3740,Planilha1!B:E,4,0) -> 1.038402
A3741: =J3741&I3741 -> LEITE EM PÓITAMBÉ | B3741: =F3741&J3741&I3741 -> 5145924LEITE EM PÓITAMBÉ | C3741: MAURICIO | D3741: JOEL | E3741: JOEL ELEOTÉRIO | F3741: 5145924 | G3741: CAFE TRES CORACOES SA | H3741: MG | I3741: ITAMBÉ | J3741: LEITE EM PÓ | K3741: 0 | L3741: 8000 | M3741: 3083.3333 | N3741: 3500 | O3741: 0 | P3741: 0 | Q3741: 0 | R3741: 0 | S3741: 0 | T3741: 0 | U3741: 0 | V3741: =VLOOKUP(A3741,Planilha1!B:E,4,0) -> 4.5971523
...

Sheet Planilha1
B2: RESUMO FORECAST SEMANAL - JAN/26
B3: =D3&C3 -> BLISTERLACTALIS | C3: LACTALIS | D3: BLISTER | E3: 13.783872
B4: =D4&C4 -> COMPOSTOLACTALIS | C4: LACTALIS | D4: COMPOSTO | E4: 7.7134688
B5: =D5&C5 -> CREME 35%LACTALIS | C5: LACTALIS | D5: CREME 35% | E5: 6.4420264
B6: =D6&C6 -> CREME UHTLACTALIS | C6: LACTALIS | D6: CREME UHT | E6: -1.4094523
B7: =D7&C7 -> DOCE DE LEITELACTALIS | C7: LACTALIS | D7: DOCE DE LEITE | E7: 5.6473514
B8: =D8&C8 -> IOGURTESLACTALIS | C8: LACTALIS | D8: IOGURTES | E8: 3.0503168
B9: =D9&C9 -> LEITE CONDENSADOLACTALIS | C9: LACTALIS | D9: LEITE CONDENSADO | E9: 1.8665072
B10: =D10&C10 -> LEITE EM PÓLACTALIS | C10: LACTALIS | D10: LEITE EM PÓ | E10: -2.8055507
B11: =D11&C11 -> LEITE UHTLACTALIS | C11: LACTALIS | D11: LEITE UHT | E11: 0.37177548
B12: =D12&C12 -> MERC + AROMLACTALIS | C12: LACTALIS | D12: MERC + AROM | E12: 0.86907188
B13: =D13&C13 -> PARMESÃOLACTALIS | C13: LACTALIS | D13: PARMESÃO | E13: 6.310327
B14: =D14&C14 -> QUEIJOSLACTALIS | C14: LACTALIS | D14: QUEIJOS | E14: -1.917131
... B40: =D40&C40 -> Não atribuídoITAMBÉ | C40: ITAMBÉ | D40: Não atribuído | E40: 0
